Workbook

Sheet Capa
F3: PROGRAMA DE EXCELÊNCIA OPERACIONAL NO TRANSPORTE AÉREO E MARÍTIMO
F8: LISTA DE VERIFICAÇÃO PEOTRAM - CICLO 2024 | N8: Versão 01
B11: Empresa (base/data): | M11: Data:
B13: Embarcação (Indicação Petrobras): | M13: Data:
B15: Embarcação (Indicação Petrobras): | M15: Data:
D17: Escopo:
D21: Resumo das operações:
D25: Observações:
D29: Auditores:
D32: Auditados:

Sheet Sumário
B2: SUMÁRIO EXECUTIVO: PONTOS FORTES DA EMPRESA: Informar quais foram os pontos fortes verificados na auditoria (tanto na base quanto na embarcação), e que contribuíram para um encaminhamento apropriado da auditoria ou que se apresentou como um destaque da empresa. RESUMO DA AUDITORIA: Informar como está a empresa nos elementos que foram auditados e dar um diagnóstico com um panorama geral de como pode se avaliar a empresa dentro deste programa de excelência (fraquezas, ameaças, oportunidades de melhoria, estrutura geral da empresa, cultura de segurança desenvolvida, e outros que acharem interessante aqui destacar).

Sheet Critério
B3: Critério de aplicação da nota de desempenho:
Q4: Percentual para cálculo
B5: N/A | C5: Não Aplicável; Não avaliado;
B6: 0 | C6: Não Evidenciado ou Não Implantado; | Q6: 0 | R6: 0
B7: 1 | C7: Evidenciado implementação com Falhas Sistemáticas ou Falhas Críticas ou Em implementação; | Q7: 1 | R7: 0.2
B8: 2 | C8: Evidenciado implementação com Falhas Pontuais; | Q8: 2 | R8: 0.5
B9: 3 | C9: Evidenciado implementação sem Falhas. | Q9: 3 | R9: 0.9
B10: 4 | C10: Evidenciadas ações e/ou boas práticas que vão além do requerido | Q10: 4 | R10: 1
B12: Classificação de criticidade das não conformidades (CNC) e prazo para implementação das ações corretivas:
B14: N/A | C14: Não Aplicável;
B15: A | C15: Crítica - Não conformidade crítica - Tomada de ação imediata para a redução do risco. Em caso de verificação de NC CRÍTICA por parte dos auditores, esta deverá ser informada imediatamente à Coordenação do PEOTRAM que avaliará qual encaminhamento a ser dado. Após a informação da NC confirmada (já na auditoria de base ou na auditoria da embarcação), deverá ser dado o tratamento das causas básicas da não conformidade no sistema BROA, com ações não podem ultrapassar 10 (dez) dias corridos da informação da NC, salvo justificativa e aprovação da Petrobras. OBS.: a eficácia das ações serão avaliadas no fechamento da pendência no sistema BROA e também no próximo ciclo de auditoria.
B16: B | C16: Grave - Não conformidade grave - Tomada de ação imediata para a redução do risco. Em caso de verificação de NC GRAVE por parte dos auditores, esta deverá ser informada imediatamente à Coordenação do PEOTRAM que avaliará qual encaminhamento a ser dado. Após a informação da NC confirmada (já na auditoria de base ou na auditoria da embarcação), deverá ser dado o tratamento das causas básicas da não conformidade no sistema BROA, com ações que não podem ultrapassar 15 (quinze) dias corridos da informação da NC, salvo justificativa e aprovação da Petrobras. OBS.: a eficácia das ações serão avaliadas no fechamento da pendência no sitema BROA e também no próximo ciclo de auditoria.
B17: C | C17: Moderado - Não conformidade moderada Após a informação das não conformidades, (informação na resposta da contestação da empresa), deverá ser dado o tratamento das causas básicas da não conformidade, e as ações de tratamento não deverão ultrapassa 30 (trinta) dias após a oficialização das NC, salvo justificativa e aprovação da Petrobras. OBS.: a eficácia das ações serão avaliadas no fechamento da pendência no sistema BROA e também no próximo ciclo de auditoria
B18: D | C18: Leve - Não conformidade leve Após a informação das não conformidades, (informação na resposta da contestação da empresa), deverá ser dado o tratamento das causas básicas da não conformidade, e as ações de tratamento não deverão ultrapassa 60 (sessenta) dias após a oficialização das NC, salvo justificativa e aprovação da Petrobras. OBS.: a eficácia das ações serão avaliadas no fechamento da pendência no sistema BROA e também no próximo ciclo de auditoria
B19: ✓ | C19: Conforme
B20: ✓✓ | C20: Item de Excelência
B22: Conforme classificação representada acima, as não‐conformidades porventura observadas deverão ser classificadas em críticas, graves, moderadas e leves, sendo:
B25: Não conformidades críticas: Não Conformidade que possa gerar risco iminente às pessoas, ao meio ambiente, à instalação ou às operações. * A Petrobras deverá ser avisada imediatamente pela equipe auditora. RISCO IMINENTE: QUE AMEAÇA SE CONCRETIZAR, QUE ESTÀ A PONTO DE ACONTECER, PRÒXIMO, IMEDIATO (ÚLTIMA BARREIRA DE CONTROLE)
B27: Não conformidades graves: a) Falta de um requisito do Sistema de Gestão da Segurança Operacional, Segurnaça Ocupacional e/ou Meio Ambiente; b) Falha relevante no atendimento a um requisito do Sistema de Gestão da Segurança Operacional, Segurnaça Ocupacional e/ou Meio Ambiente ou requisito de SMS; c) Não conformidades similares às encontradas em auditorias anteriores na mesma instalação; d) Desvio sistêmico, caracterizado por um conjunto de desvios ou por desvios similares, que ocorrem de forma repetitiva e frequente no atendimento a determinado requisito relevante.
B29: Não conformidades moderadas: a) Atendimento parcial ou insuficiente a um requisito do Sistema de Gestão da Segurança Operacional, ou requisito de SMS; b) Uma quantidade significativa de falhas leves em atender a um determinado requisito do Sistema de Gestão de Segurança Operacional.
B31: Não conformidades leves: Serão todas aquelas que possam ser consideradas como desvio ou falhas isoladas, no atendimento a um requisito de SMS e de Segurança Operacional, desde que não se enquadre nas definições anteriores; OBS.: para efeito de pontuação no PEOTRAM, será levado em consideração para este ciclo de 2023 a análise das não conformidades tratadas no ciclo anterior, bem como aquelas levantadas no ciclo atual (composição dos percentuais de atendimento).
B32: TRATAMENTO DE NC CRÍTICAS OU GRAVES: As NC CRÍTICAS ou GRAVES deverão ser tratadas dentro do ciclo em andamento, de acordo com os prazos estabelecidos no critério. As questões de Conformidade Legal, principalmente itens voltados para as NRs, caso sejam motivo de NC, serão considerados como NC GRAVE.
B33: Tratamento de ações no BROA (ou qualquer outro sistema que venha a substituí-lo): a) As pendências de auditoria serão inseridas no sistema pela equipe PETROBRAS, onde o prazo para tratamento das pendências terá início a partir da data do e-mail de envio do Relatório Final com a resposta das contestações pela empresa auditora, para a empresa auditada; b) O encerramento a ser solicitado pela empresa auditada no sistema deverá ser solicitado dentro deste status de “encerramento solicitado” para que chegue ao avaliador de forma adequada; c) O encerramento das pendências se dará no último dia estabelecido e até às 17h do dia, para que possamos corrigir qualquer inconsistência no sistema; d) As datas de atendimento às pendências serão consideradas sempre em dia útil da semana. Exemplo: se a data cair em sábado, domingo ou feriado, a equipe PETROBRAS já considerará a data útil imediatamente antes destes dias da semana. As datas de atendimento a planos da ação dos RTAs serão informados pelos pontos focais das unidades. Qualquer alteração de data a ser autorizado pelos responsáveis da PETROBRAS, será acatado mediante informação oficial, e com evidência (e-mail da PETROBRAS), a ser informada pela empresa auditada para a Coordenação do PEOTRAM; e) Caso ocorram inconsistências no sistema, a empresa auditada deverá informar imediatamente à equipe PETROBRAS para a correção em tempo hábil. Caso contrário, consideraremos como ação fechada “fora do prazo”. f) Para o correto atendimento ao tratamento das NC apontadas, será considerado o seguinte para que a pendência seja dada como atendida: - apresentação de uma análise da causa básica que levou à não conformidade; - tratamento da não conformidade a partir da causa básica levantada para evitar reincidências futuras.
B34: Classificação dos elementos críticos de segurança operacional e/ou ocupacional:
B36: 1) Equipamento crítico de segurança operacional e/ou ocupacional é qualquer equipamento ou elemento estrutural da Instalação que poderia, em caso de falha, causar ou contribuir, significativamente, para um quase acidente ou para um acidente operacional / ocupacional;
B39: 2) Sistema Crítico de Segurança Operacional é qualquer sistema de controle de engenharia que tenha sido projetado para manter a instalação dentro dos limites operacionais de segurança, parar total ou parcialmente a instalação ou um processo, no caso de uma falha na segurança operacional ou reduzir a exposição humana às consequências de eventuais falhas;
B43: 3) Procedimento crítico de segurança operacional e/ou ocupacional é um procedimento ou critério utilizado para controle de riscos operacionais/ocupacionais.
B46: Participação das inspeções do GSEM, BAD/IDF e outras auditorias na avaliação final dos critérios e na implementação dos requisitos de conformidade legal:
B48: 1) As avaliações do GSEM, auditorias de BAD/IDF ou outras avalialiações do ciclo (anexos de SMS, de normas regulamentadoras e outras), servirão, também, como embasamento para as auditorias do PEOTRAM e poderão ser utilizadas nas comparações dos itens auditados, podendo despontuar no caso de insconsistência de informações.

Sheet Elemento 01
A1: ELEMENTO 01 - LIDERANÇA, GERENCIAMENTO E RESPONSABILIDADE
A3: Requisito | B3: Descrição do Requisito | C3: Evidências para atendimento do item | D3: =IF(#REF!=Critério!$B$5,Critério!$B$5,SUM(IF(D4=Critério!$B$5,100%,D4)*SUM(#REF!),IF(D7=Critério!$B$5,100%,D7)*SUM(#REF!),IF(D11=Critério!$B$5,100%,D11)*SUM(#REF!)))/#REF! -> #REF! | E3: CNC | F3: Comentários do Auditor
A4: Responsabilidade e Autoridade | D4: =IF(#REF!=COUNTA(A5:A6),Critério!$B$5,SUMPRODUCT(#REF!,#REF!)/SUM(#REF!)) -> #REF!
A5: 1.1.1 | B5: A alta administração da empresa demonstra compromisso claro em implementar e manter a gestão de segurança, meio ambiente e saúde? | C5: Entrevistas com alta administração; a) As atribuições e responsabilidades relacionadas com a gestão de SMS e segurança operacional estão definidas e implementados a bordo e na base da empresa, levando em conta as responsabilidades das lideranças de bordo (CMT, CFM,etc) e de base (Gerentes)? b) As atribuições e responsabilidades relacionadas com a gestão de SMS, excelência operacional e segurança operacional são do conhecimento e é praticada pelos dos tripulantes e pessoal de terra que suportam às operações? Os diretores e gerentes da empresa realizam visitas periódicas nas embarcações, executando ações vinculadas à gestão de segurança? As lideranças de base e de bordo realizam auditorias comportamentais periódicas, com efetivo registros de desvios (reação das pessoas, posição das pessoas, EPI, ferramentas/equipamentos, procedimentos documentados, ordem/limpeza/arrumação) e tratamento imediato dos desvios? A empresa possui sistemática para que as lideranças e gestores realizem auditorias comportamentais periódicas e de integridade. Os gestores de manutenção, operação e SMS realizam inspeções e auditorias periódicas a bordo, visando verificar a conformidade, integridade e perfeito funcionamento dos equipamentos e dispositivos de segurança da embarcação, com efetivo registro e tratamento de desvios? | D5: 3 | E5: ✓
A6: 1.1.2 | B6: A empresa demonstra ter setores de Operação, Manutenção/Técnico, RH, SMS adequadamente estruturados, com competência técnica e articulados, para suportar operações marítimas a serviço da Petrobras? | C6: Solicitar organograma estruturado da empresa e matriz de responsabilidades para verificação da hierarquia (gerentes de operação, manutenção, SMS/HSE, RH) e autoridades dadas aos gestores. Evidências de que a bordo estes setores se articulam no suporte às operações das embarcações | D6: 3 | E6: ✓
A7: Comprometimento da Liderança | D7: =IF(#REF!=COUNTA(A8:A10),Critério!$B$5,SUMPRODUCT(#REF!,#REF!)/SUM(#REF!)) -> #REF!
A8: 1.2.1 | B8: A empresa possui sistemática para estabelecer as diversas especificações previstas em normas como: Designação profissional legalmente habilitado, habilitação, capacitação e qualificação. | C8: ISM Code, IMCA, NR 10, NR 11, NR 12, NR 13, NR 17, NR 20, NR30, NR 33, NR 34, NR 35, entre outras. Procedimento Documentado | D8: 3 | E8: ✓
A9: 1.2.2 | B9: a) A empresa designou formalmente os responsáveis legais requeridos conforme legislação, tais como Profissionais Legalmente Habilitados (PLH), profissionais designados nas NRs, dentre outros? b) Todos os serviços que requeiram atuação dos responsáveis legais estão em conformidade? | C9: Carta de Designação DPA (ISM Code / IMCA) Profissionais designados nas NR 10, NR 11, NR 12, NR 13, NR 17, NR 20, NR 33, NR 34, NR 35, entre outras. Registros que comprovem a atuação ao longo do ano do DPA e pessoas designadas para as NR | D9: 3 | E9: ✓
A10: 1.2.3 | B10: A alta administração da empresa demonstra compromisso com o tema de redução de emissões de gases de efeito estufa e apresenta ações práticas para redução de emissões? | C10: Registros que comprovem a atuação da alta liderança neste tema Ações práticas evidenciadas (ex: modos de operação, ações visando redução de consumo de diesel, gestão de manutenção, indicadores) | D10: 3 | E10: ✓
A11: Indicadores e Itens Críticos | D11: =IF(#REF!=COUNTA(A12),Critério!$B$5,SUMPRODUCT(#REF!,#REF!)/SUM(#REF!)) -> #REF!
A12: 1.3.1 | B12: A alta administração da empresa estabeleceu indicadores e metas de performance em SMS, manutenções, inspeções e excelência operacional, medindo-as e monitorando-as periodicamente, com planos de ação no caso de não atendimento? | C12: Indicadores tais como: TAR, TOR, TFCA, TG, Vazamentos, Tempo Perdido (PTP-Saúde), Falhas de DP, Cumprimentos de Plano de Manutenção (ICMP), Albalroamentos (meta zero) Medições realizadas; Planos de ação no caso de não atendimento. | D12: 3 | E12: ✓

Sheet Elemento 02
A1: ELEMENTO 02 - CONFORMIDADE LEGAL
A3: Requisito | B3: Descrição do Requisito | C3: Evidências para atendimento do item | D3: =IF(#REF!=Critério!$B$5,Critério!$B$5,SUM(IF(D4=Critério!$B$5,100%,D4)*SUM(#REF!),IF(D7=Critério!$B$5,100%,D7)*SUM(#REF!),IF(D20=Critério!$B$5,100%,D20)*SUM(#REF!),IF(D32=Critério!$B$5,100%,D32)*SUM(#REF!),IF(D37=Critério!$B$5,100%,D37)*SUM(#REF!),IF(D43=Critério!$B$5,100%,D43)*SUM(#REF!)))/#REF! -> #REF! | E3: CNC | F3: Comentários do Auditor
A4: Sistemática de Identificação e Atualização de Requisitos Legais e Outros | D4: =IF(#REF!=COUNTA(A5:A6),Critério!$B$5,SUMPRODUCT(#REF!,#REF!)/SUM(#REF!)) -> #REF!
A5: 2.1.1 | B5: a) A empresa possui sistema que identifique e atualize as legislações e normas nacionais e internacionais pertinentes às operações da empresa? b) As legislações, normas e requisitos contratuais estão inseridos em todos os estudos de risco e procedimentos que afetem a segurança das operações? | C5: Legislação Federal; Legislações Estaduais; Legislações Municipais; Outros requisitos (Exemplo: Normas NBR, Normas Regulamentadoras e Normas técnicas em geral) apresentados de forma atualizada; Lista ou Software com os requisitos legais Verificar quais são os outros requisitos aplicáveis identificados; Este documento deve apresentar a correlação entre os requisitos e os aspectos ambientais; Este documento deve apresentar a correlação entre os estudos de riscos para o caso de segurança operacional; Entrevista nas áreas operacionais. | D5: 3 | E5: ✓
A6: 2.1.2 | B6: A empresa possui grupo interno de inspeção e auditoria, para verificar a conformidade de toda sua frota às legislações marítimas, NRs, ambientais, da ANVISA, da IMCA, IMO, ISM, requisitos da Contratante? | C6: Evidenciar cronograma de inspeções/auditorias envolvendo toda a frota, com relatório de inspeção/auditoria consistente, com registros de Não Conformidades e planos de ação de tratamento de NC. Evidenciar a qualificação do(s) auditor(es) / inspetor(es) envolvidos. | D6: 3 | E6: ✓
A7: Atendimento à NR-34 | D7: =IF(#REF!=COUNTA(A8:A19),Critério!$B$5,SUMPRODUCT(#REF!,#REF!)/SUM(#REF!)) -> #REF!
A8: 2.2.1 | B8: A empresa possui profissional formalmente designado para o cumprimento da NR-34? | C8: Evidências dos registros. | D8: 3 | E8: ✓
A9: 2.2.2 | B9: Os profissionais que realizaram atividades no âmbito da NR-34 ao longo do ciclo, estão devidamente capacitados e treinados nos termos estabelecidos no item 34.3 da NR-34? | C9: Evidências dos registros (devem ser disponibilizados na auto avaliação todos os registros); Requisitos mínimos aceitáveis: a) 34.3.1 - Trabalhador qualificado: Comprovação da conclusão de curso específico para sua atividade em instituição reconhecida pelo sistema oficial de ensino; b) 34.3.2 - Profissional Legalmente Habilitado: trabalhador previamente qualificado e com registro no competente conselho de classe; c) 34.3.3. - Trabalhador capacitado :trabalhador previamente qualificado e com registro no competente conselho de classe; d) Carga mínima indicada na NR-34; e) Capacitação realizada durante horário normal de trabalho (34.3.5). | D9: 3 | E9: ✓
A10: 2.2.3 | B10: As documentações de atendimento à NR-34 estão disponíveis e conformes, como estabelecido no item 34.4 da NR-34? | C10: Empresa disponibilizar as Permissões para Trabalho, evidenciando o cumprimento dos itens constantes no 34.4 da NR-34 Entrevistas | D10: 3 | E10: ✓
A11: 2.2.4 | B11: Os trabalhos a quente realizados a bordo no ciclo anual foram realizados em conformidade com o requerido no item 34.5 da NR-34? | C11: Relação dos trabalhos a quente realizados no ciclo; Registros de atendimento integral ao item 34.5 | D11: 3 | E11: ✓
A12: 2.2.5 | B12: Os trabalhos em altura realizados a bordo no ciclo anual, foram realizados observando o requerido no item 34.6 da NR-34? | C12: Os trabalhos em altura realizados a bordo no ciclo anual, foram realizados observando o requerido no item 34.6 da NR-34? | D12: 3 | E12: ✓
A13: 2.2.6 | B13: Os trabalhos de pintura realizados a bordo no ciclo anual, foram realizados observando o requerido no item 34.9 da NR-34? | C13: Os trabalhos de pintura realizados a bordo no ciclo anual, foram realizados observando o requerido no item 34.9 da NR-34? | D13: 3 | E13: ✓
A14: 2.2.7 | B14: Os trabalhos de movimentação de cargas a bordo no ciclo anual, foram realizados observando o requerido no item 34.10 da NR-34? | C14: Relação dos equipamentos de movimentação de cargas na embarcação no ciclo anual; Registros de atendimento integral ao item 34.10 | D14: 3 | E14: ✓
A15: 2.2.8 | B15: Os equipamentos de movimentação de cargas possuem prontuários cumprindo integralmente o requerido no item 34.10.3 da NR-34? | C15: Relação de todos os equipamentos de movimentação de cargas da embarcação e seus respectivos prontuários. | D15: 3 | E15: ✓
A16: 2.2.9 | B16: Os equipamentos e acessórios de movimentação de cargas e seus acessórios estão certificados por profissionais legalmente habilitados, registrados em relatório de inspeção e com periodicidade adequada, conforme item 34.10.6 da NR-34? | C16: Relação dos certificados de todos os equipamentos de movimentação de cargas. | D16: 3 | E16: ✓
A17: 2.2.10 | B17: Os equipamentos portáteis a bordo no ciclo anual, foram realizados observando o requerido no item 34.12 da NR-34? | C17: Relação dos equipamentos portáteis na embarcação no ciclo anual; Registros de atendimento integral ao item 34.12 | D17: 3 | E17: ✓
A18: 2.2.11 | B18: As instalações elétricas provisórias a bordo no ciclo anual, foram realizados observando o requerido no item 34.13 da NR-34? | C18: Relação das instalações elétricas provisórias na embarcação no ciclo anual; Registros de atendimento integral ao item 34.13 | D18: 3 | E18: ✓
A19: 2.2.12 | B19: Os testes de estanqueidade realizados a bordo no ciclo anual, foram realizados observando o requerido no item 34.14 da NR-34? | C19: Relação dos testes de estanqueidade na embarcação no ciclo anual; Registros de atendimento integral ao item 34.14 | D19: 3 | E19: ✓
A20: Atendimento à NR-12 | D20: =IF(#REF!=COUNTA(A21:A31),Critério!$B$5,SUMPRODUCT(#REF!,#REF!)/SUM(#REF!)) -> #REF!
A21: 2.3.1 | B21: a) A empresa possui Profissional Legalmente Habilitado para fins de cumprimento da NR-12? b) O profissional é atuante e realiza todas as ações sob sua responsabilidade conforme disposto na NR-12? | C21: Evidências de designação, de atuação em registros, entrevistas; Evidenciar a formação profissional do PLH como Engenheiro Mecânico ou Engenheiro Naval e com a ART recolhida (CREA ativo). | D21: 3 | E21: ✓
A22: 2.3.2 | B22: O arranjo físico da embarcação está conforme ao estabelecido no item 12.2 da NR-12? | C22: Relatórios, fotos, Visita a bordo e registros, de aplicação de toda a NR-12 | D22: 3 | E22: ✓
A23: 2.3.3 | B23: As instalações e dispositivos elétricos nas embarcações estão conformes ao estabelecido no item 12.3 da NR-12? | C23: Relatórios, fotos, Visita a bordo e registros, de aplicação de toda a NR-12. | D23: 3 | E23: ✓
A24: 2.3.4 | B24: Os dispositivos de partida, acionamento e parada nas embarcações estão conformes ao estabelecido no item 12.4 da NR-12? | C24: Relatórios, fotos, Visita a bordo e registros, de aplicação de toda a NR-12 | D24: 3 | E24: ✓
A25: 2.3.5 | B25: Os sistemas de segurança nas embarcações estão conformes ao estabelecido no item 12.5 da NR-12? | C25: Relatórios, fotos, Visita a bordo e registros, de aplicação de toda a NR-12 | D25: 3 | E25: ✓
A26: 2.3.6 | B26: Os dispositivos de parada de emergências nas embarcações estão conformes ao estabelecido no item 12.6 da NR-12? | C26: Relatórios, fotos, Visita a bordo e registros, de aplicação de toda a NR-12 | D26: 3 | E26: ✓
A27: 2.3.7 | B27: Os componentes pressurizados das embarcações estão conformes ao estabelecido no item 12.7 da NR-12? | C27: Relatórios, fotos, Visita a bordo e registros, de aplicação de toda a NR-12 | D27: 3 | E27: ✓
A28: 2.3.8 | B28: Os riscos adicionais estão mapeados e em conformidade ao estabelecido no item 12.10 da NR-12? | C28: Relatórios, fotos, Visita a bordo e registros, de aplicação de toda a NR-12 | D28: 3 | E28: ✓
A29: 2.3.9 | B29: As manutenções, inspeções, preparação, ajustes, reparos, limpezas, sinalizações e manuais estão conformes ao estabelecido nos itens 12.11, 12.12 e 12.13 da NR-12? | C29: Relatórios, fotos, Visita a bordo e registros, de aplicação de toda a NR-12 | D29: 3 | E29: ✓
A30: 2.3.10 | B30: Para a realização de trabalhos com máquinas e equipamentos, estão estabelecidos procedimentos documentados de trabalho e segurança, conforme estabelecido no item 12.14 da NR-12? | C30: Relatórios, fotos, Visita a bordo e registros, de aplicação de toda a NR-12 | D30: 3 | E30: ✓
A31: 2.3.11 | B31: Os profissionais da empresa que realizam operação, manutenção, inspeção e demais intervenções em máquinas e equipamentos nas embarcações, estão capacitados, habilitados,qualificados e autorizados conforme estabelecido no item 12.16 da NR-12? | C31: Relação dos profissionais da empresa; registros de treinamentos (confrontando com NR-12) e entrevistas | D31: 3 | E31: ✓
A32: Atendimento à NR-33 | D32: =IF(#REF!=COUNTA(A33:A36),Critério!$B$5,SUMPRODUCT(#REF!,#REF!)/SUM(#REF!)) -> #REF!
A33: 2.4.1 | B33: a) A empresa possui Responsável Técnico para fins de cumprimento da NR-33? b) O profissional é atuante e realiza todas as ações sob sua responsabilidade conforme disposto na NR-33? | C33: Evidências de designação, de atuação em registros, entrevistas | D33: 3 | E33: ✓
A34: 2.4.2 | B34: As obrigações para a empresa referente a trabalhos em espaço confinados estão conformes o disposto no item 33.3 da NR-33? | C34: Relatórios, fotos, Visita a bordo e registros, de aplicação de toda a NR-33 | D34: 3 | E34: ✓
A35: 2.4.3 | B35: O trabalho em espaço confinado é planejado, programado, implementado e avaliado, incluindo medidas técnicas de prevenção, medidas administrativas e de capacitação estão realizados conforme o estabelecido no item 33.4 da NR-33? | C35: Relação de trabalhos em espaço confinados realizados no ciclo anual; relatórios de trabalho, visita a bordo. Somente considerar item implementado, caso para a amostra avaliada esteja 100% conforme aos itens requeridos pela NR | D35: 3 | E35: ✓
A36: 2.4.4 | B36: Os profissionais que participaram dos trabalhos em espaço confinados (autorizados, vigias, supervisores de entrada) estão devidamente capacitados conforme requerido no item 33.6 da NR-33? | C36: Relação dos profissionais, certificados de curso, ementa e carga horário de curso, listas de presença e entrevista | D36: 3 | E36: ✓
A37: Atendimento à NR-35 | D37: =IF(#REF!=COUNTA(A38:A42),Critério!$B$5,SUMPRODUCT(#REF!,#REF!)/SUM(#REF!)) -> #REF!
A38: 2.5.1 | B38: Para os trabalhos a bordo, realizados acima de 2 metros do nível inferior, onde haja risco de queda, a empresa implementou todos os requisitos estabelecidos no item 35.3 da NR-35? | C38: Relatórios, fotos, Visita a bordo e registros, de aplicação de toda a NR-35 | D38: 3 | E38: ✓
A39: 2.5.2 | B39: Os profissionais que realizam trabalhos em altura a bordo e equipes de emergência, estão capacitados conforme o requerido nos itens 35.4 e 35.7 da NR-35? | C39: Relação dos profissionais, certificados de curso, ementa e carga horário de curso, listas de presença e entrevista, confrontando com o requerido no item 35.4 | D39: 3 | E39: ✓
A40: 2.5.3 | B40: Os trabalhos em altura foram planejados, organizados e executados conforme disposto no item 35.5 da NR-35? | C40: Relação dos trabalhos em altura, Relatórios, fotos, Visita a bordo e registros, de aplicação de toda a NR-35 | D40: 3 | E40: ✓
A41: 2.5.4 | B41: Nos locais em que não for possível evitar o trabalho em altura, estão instalados e conformes os Sistemas de Proteção Contra Quedas, como requerido no item 35.6 da NR-35? | C41: Relação dos trabalhos em altura, Relatórios, fotos, Visita a bordo e registros, de aplicação de toda a NR-35 | D41: 3 | E41: ✓
...

Sheet Elemento 03
A1: ELEMENTO 03 - GESTÃO DE RISCOS
A3: Requisito | B3: Descrição do Requisito | C3: Evidências para atendimento do item | D3: =IF(#REF!=Critério!$B$5,Critério!$B$5,SUM(IF(D4=Critério!$B$5,100%,D4)*SUM(#REF!),IF(D16=Critério!$B$5,100%,D16)*SUM(#REF!)))/#REF! -> #REF! | E3: CNC | F3: Comentários do Auditor
A4: Identificação e Avaliação de Riscos | D4: =IF(#REF!=COUNTA(A5:A15),Critério!$B$5,SUMPRODUCT(#REF!,#REF!)/SUM(#REF!)) -> #REF!
A5: 3.1.1 | B5: A empresa possui processo estruturado e implementado de identificação dos perigos e gestão de riscos ocupacionais e operacionais? OBS: Entende-se como estruturado a existência de procedimentos de identificação de perigos e riscos; estudos de risco com equipes multidisciplinares; aprovação dos estudos por liderança; acompanhamento/implementação das recomendações; recomendações dos estudos de risco estarem contemplada nos procedimentos operacionais | C5: Procedimento documentado; Relatório de Análises de Riscos; Relatório de Análise Preliminar de Riscos; Relatório de Análise Preliminar de Perigos; Contemplam entre outros: Intoxicação, Doenças contagiosas, Trauma, desastres naturais, ação de terceiros (exemplos: terrorismo e vandalismo). | D5: 3 | E5: ✓
A6: 3.1.2 | B6: Os participantes de estudos de riscos possuem treinamento em técnicas de avaliação e gestão de riscos? | C6: Registros de treinamento e entrevistas | D6: 3 | E6: ✓
A7: 3.1.3 | B7: Para estudos de riscos para segurança operacional (ou segurança técnica da embarcação), são utilizadas técnicas estruturadas DE CLASSIFICAÇÃO DE RISCO (SEVERIDADE, FREQUÊNCIA - MODERADO, TOLERÁVEL , NÃO TOLERÁVEL) como as preconizadas no item 4 para embarcações DP o ASOG, conforme norma IMCA? | C7: Procedimentos documentados, específicos e mais elaborados para: HAZOP; FMEA / ASOG (Planilha de tomada de decisões); HAZID; Bow Tie; | D7: 3 | E7: ✓
A8: 3.1.4 | B8: Nos estudos de risco de segurança operacional, é aplicada uma Matriz de Tolerabilidade de Riscos, abrangendo categorias severidade x freqüência de eventos que possam provocar danos às pessoas, patrimônio, meio ambiente e imagem, em técnica igual ou similar ao previsto na Norma Petrobras N-2782 ? | C8: Verificar se os riscos foram categorizados conforme matriz de tolerabilidade. | D8: 3 | E8: ✓
A9: 3.1.5 | B9: A empresa possui uma sistemática que verifique a qualidade das análises de risco, contemplando, obrigatoriamente, no mínimo: a) A condução por um líder com treinamento na técnica a ser utilizada; b) A participação de equipe multidisciplinar (Operação, SMS e Manutenção), com composição e dimensionamento adequados à amplitude, profundidade e natureza do estudo; c) Aprovação por nível hierárquico superior do estudo e suas recomendações; d) Garantia de rastreabilidade e controle de revisão dos estudos; e) Garantia da rastreabilidade das ações adotadas relativas às implementações das recomendações; f) Matriz de Tolerabilidade de Riscos, que correlacione a freqüência dos eventos indesejados e a severidade das conseqüências esperadas. | C9: Estudo de risco realizado. | D9: 3 | E9: ✓
A10: 3.1.6 | B10: A liderança de base da contratada, monitora e registra os percentuais de implementação das recomendações de estudos de risco na sua frota, bem como a qualidade das análises de risco? | C10: Estudo de risco realizado. | D10: 3 | E10: ✓
A11: 3.1.7 | B11: a) As análises de riscos contemplam acidentes e incidentes de segurança operacional ocorridos na própria empresa e os acidentes/alertas compartilhados pela PETROBRAS? b) nos estudos de Análise de Riscos estão de uma forma que considera o histórico dos acidentes, e estão sendo divulgados para toda a tripulação? | C11: Verificar se o estudo de riscos leva em consideração a análise histórica de acidentes; Incêndio; Explosão; Vazamento de produtos químicos; Avaria da embarcação; Alagamento; Perda de posicionamento; Colisão/abalroamento; Black out; E outros. | D11: 3 | E11: ✓
A12: 3.1.8 | B12: As análises de riscos a bordo levam em consideração os requisitos dos Guias e dos Manuais de Segurança da Petrobras? | C12: Levantamento de aspectos e impactos e perigos e danos; Relatório de Análises de Riscos; Relatório de Análise Preliminar de Riscos; Relatório de Análise Preliminar de Perigos; Guia de Operações entre Embarcação de Apoio Marítimo e Unidade Marítima. | D12: 3 | E12: ✓
A13: 3.1.9 | B13: A empresa evidencia que os procedimentos das tarefas rotineiras são baseados em avaliações de aspectos, impactos e perigos e riscos? | C13: Procedimento documentado e acompanhamento de tarefas realizadas a bordo (confrontar padrão x operação) | D13: 3 | E13: ✓
A14: 3.1.10 | B14: A empresa evidencia que para tarefas novas, não rotineiras ou não planejadas, que também realiza avaliação prévia dos aspectos, impactos, perigos e riscos? | C14: Procedimento documentado; Relatório de Análises de Riscos; Relatório de Análise Preliminar de Riscos; Relatório de Análise Preliminar de Perigos; | D14: 3 | E14: ✓
A15: 3.1.11 | B15: Os estudos de risco de segurança operacional abrangem, no mínimo os cenários de: abalroamento, colisão, incêndio, naufrágio, perdas de posição, derivas, alagamentos, homem ao mar, emborcamento de botes, danos na estrutura da embarcação, acidentes envolvendo movimentação de cargas, acidentes envolvendo movimentação de combustíveis, situações de diving less? | C15: Estudos de risco cobrindo cada um dos indicados como mínimo; Estudo de tecnologias que evitem a atividade de mergulho. | D15: 3 | E15: ✓
A16: Gerenciamento de Riscos | D16: =IF(#REF!=COUNTA(A17:A20),Critério!$B$5,SUMPRODUCT(#REF!,#REF!)/SUM(#REF!)) -> #REF!
A17: 3.2.1 | B17: a) A bordo estão implementadas as ações de prevenção e/ou mitigação dos estudos de riscos avaliados? b) As barreiras (salvaguardas) identificadas na análise de riscos estão íntegras? | C17: Verificação em campo: - Entrevistas na área operacional; - Descumprimento de procedimentos; - Falta de manutenção em equipamentos críticos; - Equipamentos críticos inoperantes; - Não implementação das ações de gerenciamento dos riscos; - EPIs; Verificar barreiras que cubram os cenários críticos (ex: abalroamento, incêndio, perda de posição, movimentação de cargas, etc)? | D17: 3 | E17: ✓
A18: 3.2.2 | B18: Tanto nos estudos de risco, quanto a bordo, a contratada determina e implementa controles seguindo a hierarquia de: a) eliminação; b) substituição; c) controles de engenharia; d) sinalização, alertas e/ou controles administrativos; e) equipamentos de proteção individual (EPI)? | C18: Verificação em campo | D18: 3 | E18: ✓
A19: 3.2.3 | B19: Nas entrevistas a bordo, a força de trabalho tem conhecimento dos riscos a que estão submetidos e as ações de controle? | C19: Verificação em campo e entrevistas | D19: 3 | E19: ✓
A20: 3.2.4 | B20: a) Foram estabelecidos gatilhos para revisão dos levantamentos de aspectos e impactos e perigos e danos e para os estudos de riscos para segurança operacional? Obs: Exemplos de gatilhos: I) dados oriundos de acidentes e incidentes; II) simulados de emergência; III) materiais enviados pela Petrobras (alertas de SMS, abrangência de acidentes, etc.), ou gerados pela própria empresa, aplicáveis às suas atividades; entre outros. | C20: Procedimento documentado; Levantamento de aspectos e impactos e perigos e danos; Estudos de riscos Registros de abrangências dos Alertas de SMS Registros de avaliação dos simulados Registros de investigação de acidentes e incidentes. O potencial impacto ambiental de todas as atividades da empresa e da embarcação foi dimensionado e analisado. | D20: 3 | E20: ✓

Sheet Elemento 04
A1: ELEMENTO 04 - OPERAÇÃO
A3: Requisito | B3: Descrição do Requisito | C3: Evidências para atendimento do item | D3: =IF(#REF!=Critério!$B$5,Critério!$B$5,SUM(IF(D4=Critério!$B$5,100%,D4)*SUM(#REF!),IF(D12=Critério!$B$5,100%,D12)*SUM(#REF!),IF(D16=Critério!$B$5,100%,D16)*SUM(#REF!),IF(D18=Critério!$B$5,100%,D18)*SUM(#REF!),IF(D23=Critério!$B$5,100%,D23)*SUM(#REF!),IF(D28=Critério!$B$5,100%,D28)*SUM(#REF!),IF(D32=Critério!$B$5,100%,D32)*SUM(#REF!),IF(D40=Critério!$B$5,100%,D40)*SUM(#REF!),IF(D45=Critério!$B$5,100%,D45)*SUM(#REF!),IF(D47=Critério!$B$5,100%,D47)*SUM(#REF!)))/#REF! -> #REF! | E3: CNC | F3: Comentários do Auditor
A4: Geral | D4: =IF(#REF!=COUNTA(A5:A11),Critério!$B$5,SUMPRODUCT(#REF!,#REF!)/SUM(#REF!)) -> #REF!
A5: 4.1.1 | B5: Há sistemática para definição e gestão de equipamentos críticos? a) A relação dos elementos críticos foi validada pela liderança? | C5: Procedimentos documentados; Definição de sistemas e equipamentos críticos; Lista de equipamentos; Registros; Análise de risco. | D5: 3 | E5: ✓
A6: 4.1.2 | B6: Existe sistemática implementada de Verificação de Conformidade de Procedimentos - VCP? | C6: Procedimento baseado em análise de risco; Relatórios; Lista de padrões críticos; Lista de Verificação: a) Inclui os procedimentos críticos? b) Existe um cronograma e o mesmo está sendo cumprido? c) A liderança participa do processo? d) Os equipamentos e sistemas críticos de segurança operacional possuem procedimentos documentados de operação? | D6: 3 | E6: ✓
A7: 4.1.3 | B7: A empresa possui gestão de operações críticas? | C7: As operações críticas foram mapeadas através de análise de risco e procedimentadas? a) Atracação, desatracação e navegação; b) Aproximação de zona de 500 metros; c) Transferência de fluidos; d) Transporte/transbordo de pessoas; e) Pull-in/Pull-out; f) Movimentação de cargas; g) Hook-up; h) Pull back; i) Operações simultâneas; j) Contenção e recolhimento de óleo; k) Limites meteoceanográficos definidos para as operações; | D7: 3 | E7: ✓
A8: 4.1.4 | B8: a) A embarcação possui procedimento documentado para solicitação de autorização à Unidade Marítima antes de entrar na zona de 500 metros, bem como em toda operação dentro da zona de 500 metros? b) Existem registros destas comunicações no diário de bordo? | C8: Procedimento documentados; Constatação durante operação; Registros prévios de aproximações; Verificar registros que comprovem; Protocolos de Aproximação; Registro fotográfico do diário de bordo; Procedimento de Bump Test; Certificado de Calibração dos detectores de gases; Treinamento no procedimento de Bump Test. | D8: 3 | E8: ✓
A9: 4.1.5 | B9: A embarcação utiliza os protocolos de aproximação e se certifica da ausência de gases tóxicos a partir de eventos de abertura de vents nas plataformas ? | C9: Registros de aproximação e evidências de utilização do protocolo; Registro da medição de gases. | D9: 3 | E9: ✓
A10: 4.1.6 | B10: a) Existe procedimento para operações simultâneas? b) O procedimento detalha quais operações não podem ser realizadas simultaneamente? c) Existe planejamento para a realização das operações simultâneas? d) Existe estudos de riscos para a realização das operações simultâneas ? | C10: Procedimentos documentados; Lista de verificação; Registros; Constatação visual; Treinamentos. | D10: 3 | E10: ✓
A11: 4.1.7 | B11: As permissões para trabalho emitidas estão de acordo com o procedimento existente: I) está dentro dos serviços que exigem emissão de PT? II) estão os responsáveis: pela emissão, execução e encerramento/revalidação da PT? III) existe a elaboração da APR e realização das inspeções prévias antes dos inícios das tarefas? IV) existe a identificação dos tipos de isolamentos de energia necessários? V)existe a identificação das medições e monitoramentos necessários à liberação do trabalho e informações das FISPQ? VI) existe a identificação e planejamento das medidas de resgates e das operações simultâneas (SIMOPS)? VII)existe a identificação das áreas conflitantes? VIII) existe a elaboração em três vias e sistemáticas para acompanhamento das emissões das PTs? IX) Estão definidos os critérios de rastreabilidade das PTs (ordem seqüencial)? | C11: Verificar PT emitida; Procedimentos documentados; Lista de verificação; Regras de Ouro da Petrobras; NR 10 (quando aplicável), NR 20, NR 30, NR 33, NR 34 e NR 35, etc; Auditoria realizada; Consolidação do ano anterior ao ciclo atual. | D11: 3 | E11: ✓
A12: Transporte de Pessoas | D12: =IF(#REF!=COUNTA(A13:A14),Critério!$B$5,SUMPRODUCT(#REF!,#REF!)/SUM(#REF!)) -> #REF!
A13: 4.2.1 | B13: Está sendo seguido o que está estabelecido na NR-37, itens 37.11.4.1 e 37.11.5 para a transferência de pessoas ? | C13: Procedimentos documentados; NR-37. | D13: 3 | E13: ✓
A14: 4.2.2 | B14: a) Os efeitos das condições de tempo e mar são considerados nas operações de transferência de pessoas? b) O anemômetro está operacional e calibrado? | C14: Procedimento documentado. | D14: 3 | E14: ✓
A15: Transporte de Cargas e Granéis
A16: Operação com carga embalada / contêineres | D16: =IF(#REF!=COUNTA(A17),Critério!$B$5,SUMPRODUCT(#REF!,#REF!)/SUM(#REF!)) -> #REF!
A17: 4.3.1 | B17: a) Existe um procedimento para transporte de materiais e fontes radioativas de acordo com normas da CNEN estabelecidas (fontes e material de ocorrência natural - NORM - com baixa atividade)? b) A arrumação e cuidados com as cargas radioativas a bordo é realizada conforme diretrizes do código IMDG Code? | C17: Documentações; Autorizações e licenças. | D17: 3 | E17: ✓
A18: Operação com granéis líquidos/sólidos | D18: =IF(#REF!=COUNTA(A19:A22),Critério!$B$5,SUMPRODUCT(#REF!,#REF!)/SUM(#REF!)) -> #REF!
A19: 4.3.2 | B19: a) Existe procedimento para as operações de transferência de granéis poluentes? b) O procedimento contempla a utilização de bandeja de contenção sob a conexão do magote da Unidade Marítima ou píer com o mangote da embarcação e orientações para o tamponamento dos embornais? c) A bandeja de contenção possui capacidade suficiente, aproximadamente 200 litros para as tomadas de abastecimentos e 20 litros para suspiros conforme NORMAN 1, para evitar que o óleo seja derramado no convés? d) Existe kit de contenção/SOPEP próximo? e) Os bujões das bandejas de contenção e dos embornais estão disponíveis e com boa vedação? | C19: Procedimentos documentados; Constatação durante operação; Constatação Visual; Treinamento. | D19: 3 | E19: ✓
A20: 4.3.3 | B20: Há previsão no procedimento informando de que o Comandante somente inicia uma operação de transferência de granéis líquidos quando os mangotes utilizados para o bombeamento tenham sido totalmente desenrolados do carretel da Unidade Marítima? | C20: Procedimento documentado; Constatação durante operação. | D20: 3 | E20: ✓
A21: 4.3.4 | B21: Há previsão no procedimento informando de que o Comandante somente inicia uma operação de transferência de granéis líquidos quando os mangotes utilizados para o bombeamento estão visíveis no mar através da utilização de flutuadores (mínimo quatro ao longo do mangote e, caso haja emenda, também um de cada lado)? | C21: Procedimento documentado; Constatação durante operação. | D21: 3 | E21: ✓
A22: 4.3.5 | B22: a) Os mangotes e conexões são inspecionados, a cada uso, visando a identificação de áreas enfraquecidas ou desgastadas e haste de válvulas danificadas? b) Os mangotes da embarcação estão armazenados de forma longitudinal em cabides próprios sem dobras, fissuras e/ou aduchados? c) Os Mangotes de transferência de água da embarcação encontram-se armazenados em cabides próprios, tamponados e de forma a não permitir contato com agentes biológicos ou patogênicos? | C22: Procedimento documentado; Registro de inspeção; Certificado de Qualidade dos mangotes. | D22: 3 | E22: ✓
A23: Operação de Recolhimento de Óleo | D23: =IF(#REF!=COUNTA(A24:A27),Critério!$B$5,SUMPRODUCT(#REF!,#REF!)/SUM(#REF!)) -> #REF!
A24: 4.4.1 | B24: a) Existe e está sendo cumprido procedimento de manutenção da posição de prontidão? b) O procedimento inclui preocupação com a identificação de possíveis colisões e abalroamentos? c) O procedimento está em português e outras línguas aplicáveis? d) O procedimento foi elaborado/revisado nos últimos 18 meses? e) Existe evidência de treinamento da tripulação? f) O procedimento inclui ações de resposta para incidentes previstos na análise de risco? | C24: Procedimento documentado. | D24: 3 | E24: ✓
A25: 4.4.2 | B25: a) Existe e está sendo cumprido procedimento para a operação de contenção e recolhimento de óleo? b) Estes procedimentos contemplam cuidados com movimento de cargas (barco de apoio e recolhedor-skimmer), cabos tensionados, colisão, abalroamento, aproximação em área com atmosfera potencialmente explosiva, navegação segura com barreiras e condições ambientais limites (estado de mar)? c) O procedimento está em português e outras línguas aplicáveis? d) O procedimento foi elaborado/revisado nos últimos 18 meses? e) Existe evidência de treinamento da tripulação? f) O procedimento inclui ações de resposta para incidentes previstos na análise de risco? | C25: Procedimento documentado. | D25: 3 | E25: ✓
A26: 4.4.3 | B26: a) Existe e está sendo cumprido procedimento para operação de dispersão mecânica? b) Este procedimento contempla cuidados com colisão, abalroamento e aproximação em área com atmosfera potencialmente explosiva? c) O procedimento está em português e outras línguas aplicáveis? d) O procedimento foi elaborado/revisado nos últimos 18 meses? e) Existe evidência de treinamento da tripulação? f) O procedimento inclui ações de resposta para incidentes previstos na análise de risco? | C26: Procedimento documentado. | D26: 3 | E26: ✓
A27: 4.4.4 | B27: a) Existe e está sendo cumprido procedimento para operação de dispersão química? b) Este procedimento contempla cuidados com a manipulação de produtos químicos perigosos, medição de vazão e autorização expressa pela Petrobras? c) O procedimento está em português e outras línguas aplicáveis? d) O procedimento foi elaborado/revisado nos últimos 18 meses? e) Existe evidência de treinamento da tripulação? f) O procedimento inclui ações de resposta para incidentes previstos na análise de risco? | C27: Procedimento documentado. | D27: 3 | E27: ✓
A28: Equipamentos para Operação de Reboque | D28: =IF(#REF!=COUNTA(A29:A31),Critério!$B$5,SUMPRODUCT(#REF!,#REF!)/SUM(#REF!)) -> #REF!
A29: 4.5.1 | B29: Existe procedimento de inspeção do equipamento de reboque / Emergência manuseio por um oficial competente da embarcação e seus registros são mantidos? | C29: Procedimento documentado; Registro de inspeção; Certficação. | D29: 3 | E29: ✓
A30: 4.5.2 | B30: Existe procedimento estabelecendo limites operacionais para que a tarefa seja realizada de forma segura ? | C30: Procedimento documentado. | D30: 3 | E30: ✓
A31: 4.5.3 | B31: Todo o equipamento de reboque está certificado, os certificados se encontram válidos e estão disponíveis a bordo? | C31: Certificados | D31: 3 | E31: ✓
A32: Convés | D32: =IF(#REF!=COUNTA(A33:A39),Critério!$B$5,SUMPRODUCT(#REF!,#REF!)/SUM(#REF!)) -> #REF!
A33: 4.6.1 | B33: As seguintes Zonas de Segurança das embarcações que transportam carga estão demarcadas de forma visível no convés: a) as Safety Zones - proteção de pessoas? b) as Dangerous Good Area - para cargas perigosas? | C33: Constatação visual | D33: 3 | E33: ✓
A34: 4.6.2 | B34: Escotilhas, portas, etc. que dão acesso aos convés possuem sinalização para serem mantidas fechadas durante a navegação? | C34: Procedimento documentado; Constatação visual; Certificados. | D34: 3 | E34: ✓
A35: 4.6.3 | B35: As condições de estanqueidade de qualquer abertura acima da borda livre nos conveses (portas de visita, agulheiro, escotilhões) são mantidas? | C35: Constatação visual; Checklist . | D35: 3 | E35: ✓
A36: 4.6.4 | B36: As condições dos suspiros,tela corta chamas e redes estão em boas condições e as válvulas de fechamento estão operacionais? | C36: Constatação visual; Checklist. | D36: 3 | E36: ✓
A37: 4.6.5 | B37: a) Os equipamentos de içamento e movimentação de carga (guindastes, pau de carga, etc.) possuem a identificação do SWL (Safe Working Load) e tabela de cargas? b) Os certificados dos equipamentos de movimentação de carga estão disponíveis a bordo e encontram-se válidos? | C37: Procedimento documentado; Constatação visual; Certificados. | D37: 3 | E37: ✓
A38: 4.6.6 | B38: a) Os acessórios de içamento de carga (eslingas, correntes, cabos, olhais, etc.) possuem identificação do SWL (Safe Working Load) apropriado para as cargas que serão sustentadas? b) Os certificados dos acessórios de içamento de carga estão disponíveis a bordo e encontram-se válidos? | C38: Procedimento documentado; Constatação visual; Certificados. | D38: 3 | E38: ✓
A39: 4.6.7 | B39: a) Estão em boas condições de conservação os equipamentos que possam apresentar risco de queda sobre a tripulação (holofotes, câmeras, antenas, etc.)? b) Existe dispositivo de segurança adicional-trava quedas- (cabos, correntes) para fixação de luminárias, câmeras, antenas, etc? | C39: Constatação visual; Checklist. | D39: 3 | E39: ✓
A40: Praça de Máquinas | D40: =IF(#REF!=COUNTA(A41:A44),Critério!$B$5,SUMPRODUCT(#REF!,#REF!)/SUM(#REF!)) -> #REF!
A41: 4.7.1 | B41: a) Os obstáculos, ressaltos e partes móveis de máquinas ou equipamentos estão efetivamente protegidas, sinalizadas e pintadas? b) Rotas de fuga estão adequadamente sinalizadas? | C41: Constatação visual; Checklist. | D41: 3 | E41: ✓
...

Sheet Elemento 05
A1: ELEMENTO 05 - SEGURANÇA TÉCNICA E EFICIÊNCIA ENERGÉTICA
A3: Requisito | B3: Descrição do Requisito | C3: Evidências para atendimento do item | D3: =IF(#REF!=Critério!$B$5,Critério!$B$5,SUM(IF(D4=Critério!$B$5,100%,D4)*SUM(#REF!),IF(D13=Critério!$B$5,100%,D13)*SUM(#REF!),IF(D23=Critério!$B$5,100%,D23)*SUM(#REF!)))/#REF! -> #REF! | E3: CNC | F3: Comentários do Auditor
A4: Segurança na Navegação | D4: =IF(#REF!=COUNTA(A5:A12),Critério!$B$5,SUMPRODUCT(#REF!,#REF!)/SUM(#REF!)) -> #REF!
A5: 5.1.1 | B5: A empresa marítima designou pessoal de base devidamente qualificado, para ser responsável pelos procedimentos de navegação da companhia? | C5: Registro da designação; Evidências de qualificação do pessoal responsável pelos procedimentos de navegação da companhia. | D5: 3 | E5: ✓
A6: 5.1.2 | B6: A empresa possui procedimentos documentados e sistemática robustos e abrangentes de segurança na navegação e monitoramento de manobras, incluindo atracações, desatracações, navegação e operações com plataformas, visando a antecipar e tratar situações que possam provocar acidentes? | C6: Procedimentos documentados; Definição de procedimento crítico Lista de equipamentos e sistemas versus procedimentos Registros Padrões de manobra dos portos onde a empresa opere | D6: 3 | E6: ✓
A7: 5.1.3 | B7: A empresa possui procedimento documentado e aplica um efetivo Gerenciamento de Passadiço (BRM - Bridge Resource Management)? | C7: Procedimento documentado; Planejamento do trajeto; Identificação de incidentes e desvios; Execução e monitoramento do trajeto; Navegação eletrônica; Cartas náuticas eletrônicas; Relação entre prático e equipe de passadiço; STCW; Reg. A-II/1 for Bridge Resource Management; Reg. A-III/1 for Engine-room Resource Management; Reg. A-II/2 and A-III/2 for Use Leadership and Managerial Skills; Reg. A-II/1, A-III/1 and A-III/6 for Application of Leadership and Teamworking Skills. | D7: 3 | E7: ✓
A8: 5.1.4 | B8: Os equipamentos de navegação estão operacionais? | C8: Verificação na embarcação | D8: 3 | E8: ✓
A9: 5.1.5 | B9: O setor responsável pelos procedimentos de navegação da empresa realiza verificações periódicas nas práticas operacionais, revisando os procedimentos, realizando VCP? | C9: Procedimentos documentados;. Revisões de VCP | D9: 3 | E9: ✓
A10: 5.1.6 | B10: A empresa possui sistema que garanta que só contrate oficiais (imediatos, oficiais, pilotos, chefes) devidamente formados e habilitados pela autoridde marítima? | C10: Verificar sistemática de contratação dos oficiais; | D10: 3 | E10: ✓
A11: 5.1.7 | B11: São realizadas auditorias nas práticas de navegação, atracação, desatracações e operações com unidades marítimas, para verificar conformidade, práticas adequadas, revisando-as quando necessário? | C11: Verificar auditorias realizadas | D11: 3 | E11: ✓
A12: 5.1.8 | B12: Os oficiais (comandantes, imediatos, pilotos) passam periodicamente por treinamentos, e reciclagens, através de simuladores, em consonância com a IMCA 117? | C12: Treinamentos realizados Entrevistas com comandantes, imediatos, pilotos OBS.: Quando este item for classificado como NA, o auditor deverá fazer uma ressalva informando que a empresa não está habilitada para ofertar embarcações com DP. | D12: 3 | E12: ✓
A13: Atividades especializadas - Operações de posicionamento dinâmico (DP) | D13: =IF(#REF!=COUNTA(A14:A22),Critério!$B$5,SUMPRODUCT(#REF!,#REF!)/SUM(#REF!)) -> #REF!
A14: 5.2.1 | B14: A empresa possui um departamento de garantia de DP estruturado? | C14: Apresentação do organograma da empresa; OBS.: Quando este item for classificado como NA, o auditor deverá fazer uma ressalva informando que a empresa não está habilitada para ofertar embarcações com DP. a) Avaliação de competências formais do pessoal chave de DP - IMCA 117; b) Desenvolvimento da matriz de treinamento de pessoal chave de DP; c) Acompanhamento e aplicação da matriz de treinamento desenvolvida; d) Desenvolvimento dos padrões de familiarização específicos para cada embarcação; e) Acompanhamento e aplicação dos padrões de familiarização desenvolvidos; f) Acompanhamento e registro de experiência de cada tripulante em cada tipo de embarcação; g) Desenvolvimento de simulados de emergência em DP; h) Desenvolvimento das matrizes de simulados para cada embarcação; i) Acompanhamento e registro da execução dos simulados de cada tripulante para cada embarcação; j) Criação de um plano de desenvolvimento contínuo do pessoal chave de DP; k) Acompanhamento e aplicação dos planos de desenvolvimento contínuo; l) Desenvolvimento de um programa de avaliação de competência (assessment) do pessoal chave de DP; m) Acompanhamento e aplicação das avaliações de competência do pessoal chave de DP; n) Retroalimentação dos gaps identificados nas avaliações de competência na matriz de treinamento específica do tripulante em questão; o) Rotina de acompanhamento de embarque de tripulantes e garantia de atendimento aos requisitos; p) Gestão da documentação técnica necessária a bordo: FMEA, FMEA Trials, Manual de Operações de DP, Procedimentos Operacionais (Checklists diversos, CAMO, ASOG, Manobras de Emergência), manuais técnicos de equipamentos etc.; q) Acompanhamento da execução de FMEA Trials e DP annual Trials; r) Acompanhamento investigativo de qualquer evento indesejável de DP – qualquer evento, desde uma simples degradação até o evento topo de perda de posicionamento e controle da embarcação; | D14: 3 | E14: ✓
A15: 5.2.2 | B15: As embarcações DP da empresa possuem um manual de operações DP? | C15: Apresentação dos manuais de todas as embarcações. OBS.: Quando este item for classificado como NA, o auditor deverá fazer uma ressalva informando que a empresa não está habilitada para ofertar embarcações com DP. | D15: 3 | E15: ✓
A16: 5.2.3 | B16: As embarcações da empresa possuem um Checklist pré-operacional para garantir a correta configuração da embarcação conforme preconiza a IMO MSC 1580? | C16: Apresentação de pelo menos um Checklist preenchido pelas embarcações da empresa. OBS.: Quando este item for classificado como NA, o auditor deverá fazer uma ressalva informando que a empresa não está habilitada para ofertar embarcações com DP. | D16: 3 | E16: ✓
A17: 5.2.4 | B17: Existe para a embarcação auditada um CAM ASOG para cada tipo de operação e locação (interface com unidade marítima)? | C17: Apresentação do conjunto de CAM ASOG específico por operação da embarcação. OBS.: Quando este item for classificado como NA, o auditor deverá fazer uma ressalva informando que a empresa não está habilitada para ofertar embarcações com DP. | D17: 3 | E17: ✓
A18: 5.2.5 | B18: Existe um programa sob responsabilidade do setor de garantia de DP para auditoria dos checklists pré-operacionais de DP? | C18: Apresentação do programa, cronogramas, auditorias e resultados. | D18: 3 | E18: ✓
A19: 5.2.6 | B19: As contratações de novos tripulantes são feitas com o auxílio e avaliação do setor de garantia de DP? | C19: Apresentação do fluxo de contratação adotado pela empresa. | D19: 3 | E19: ✓
A20: 5.2.7 | B20: O setor de garantia de DP possui um programa de avaliação de competência estruturado contendo minimamente os tópicos abordados abaixo? a) Programa de avaliação e auditoria pela liderança de bordo; b) Programa de auditoria por especialista (externo à embarcação) em operações (náutica e máquinas) à bordo das embarcações; c) Provas e simulados para verificação de competências. | C20: Apresentação do programa, cronograma e resultados. | D20: 3 | E20: ✓
A21: 5.2.8 | B21: O setor de garantia de DP controla os processos relacionados FMEAS, FMEA Trials e DP Annual Trials. a) Acompanhar a execução dos testes de FMEA Trials e garantir a solução das não conformidades encontradas durantes os testes; b) Supervisionar os testes de DP Annual Trials, garantindo sua melhor execução e resolução das não conformidades encontradas; c) Desenvolver uma matriz de acompanhamento de execução de FMEA Trials e DP Annual Trials pelos tripulantes. | C21: Apresentação das atribuições do setor de garantia de DP, avaliação do modelo de gestão de FMEA Trials e DP Annual Trials. Avaliar e apresentar ao menos 3 FMEAS para verificação de excelência. Auditar a quitação de itens não conformes encontrados no último DP Annual Trials de 3 embarcações. | D21: 3 | E21: ✓
A22: 5.2.9 | B22: Os FMEAS das embarcações apresentam minimamente os seguintes itens: i. Modo de Falha ii. Causas iii. Probabilidade iv. Efeito Local v. Efeito Final vi. Criticidade | C22: a) A embarcação DP é submetida ao teste do sistema DP a cada 5 anos? b) Existe a verificação do quanto o FMEA atual se diferencia do Inicial, assim como são determinados os ajustes no sistema e equipamentos que devem ser feitos a fim de tornar o sistema DP ao estado de intacto, confiável? (IMCA 166) OBS.: Quando este item for classificado como NA, o auditor deverá fazer uma ressalva informando que a empresa não está habilitada para ofertar embarcações com DP. | D22: 3 | E22: ✓
A23: BAIXO CARBONO | D23: =IF(#REF!=COUNTA(A24:A29),Critério!$B$5,SUMPRODUCT(#REF!,#REF!)/SUM(#REF!)) -> #REF!
A24: 5.3.1 | B24: a) A empresa está com sistemática estabelecida para acompanhamento dos gases de efeito estufa (GEE), seguindo o estabelecido na ISO 14064, se pautando nos 05 (cinco) princípios da ABNT NBR ISO 14064-1 e ABNT NBR ISO 14064-2 , a serem: relevância, integralidade, consistência, precisão, transparência e conservadorismo? b) A empresa está com seu inventário atualizado sobre a emissão de Gases de Efeito Estufa? c) Existe a Mensuração, publicação de inventário de emissão de gases de efeito estufa pela frota de embarcações, e verificação por uma terceira parte independente, conforme os critérios do Programa Brasileiro GHG Protocol em http://www.ghgprotocolbrasil.com.br/especificacoes-de-verificacao/?locale=pt-br ou entidade reconhecida internacionalmente”; | C24: Procedimentos da ISO 14064; Protocolos do Programa Brasileiro GHG. | D24: 3 | E24: ✓
A25: 5.3.2 | B25: A política de proteção ambiental e o plano de gestão estão em vigor e contemplam ações de longo prazo, metas específicas de redução de emissões ? | C25: Verificar política de proteção ambiental e implementação de um plano de gestão ambiental. | D25: 3 | E25: ✓
A26: 5.3.3 | B26: Foram sistematicamente identificadas todas as fontes de emissões marinhas e atmosféricas atribuíveis às atividades da empresa e da embarcação? | C26: Mapeamento das fontes. | D26: 3 | E26: ✓
A27: 5.3.4 | B27: A empresa adota medidas técnicas/de engenharia em suas embarcações, que comprovem a redução das emissões de CO2 e de consumo de diesel? | C27: Verificar procedimentos e implementação das medidas determinadas. | D27: 3 | E27: ✓
A28: 5.3.5 | B28: O plano de gestão ambiental inclui a gestão de combustível, (garantir conformidade regulamentar, eficiência energética e emissões reduzidas), com uso eficiente de energia e inclui ações de desempenho ambiental? | C28: Verificar o plano de gestão ambiental e ações implementadas. | D28: 3 | E28: ✓
A29: 5.3.6 | B29: A empresa explora novas idéias e novas tecnologias, e se engaja em parcerias tecnológicas relacionadas à performance de atuação relacionada ao desempenho ambiental? | C29: Verificar participações em eventos, seminários, parcerias existentes. | D29: 3 | E29: ✓

Sheet Elemento 06
A1: ELEMENTO 06 - MANUTENÇÃO E CONFIABILIDADE DE EMBARCAÇÕES
A3: Requisito | B3: Descrição do Requisito | C3: Evidências para atendimento do item | D3: =D4 -> #REF! | E3: CNC | F3: Comentários do Auditor
A4: Manutenção Corretiva e Preventiva | D4: =IF(#REF!=COUNTA(A5:A27),Critério!$B$5,SUMPRODUCT(#REF!,#REF!)/SUM(#REF!)) -> #REF!
A5: 6.1.1 | B5: Toda embarcação da empresa é coberta por um sistema de manutenção planejado e o inventário de peças sobressalentes (estoque mínimo, pontos de ressuprimento) existente reflete a estratégia de manutenção da empresa? | C5: Sistema de manutenção; Inventário de sobressalentes; Registros de manutenção; Procedimento. | D5: 3 | E5: ✓
